# Critical Bugs Found During Testing - 2025-08-25

## STATUS: ✅ FIXED - 2025-08-24

All critical bugs have been successfully fixed and tested in the bracket_orders.py module.

### Fixes Applied:
1. **Unprotected Position Risk**: Added emergency position closure when protective orders fail
2. **Input Validation**: Added proper validation for entry_type and entry_price parameters
3. **Recovery Manager**: Fixed attribute access (getattr instead of direct access)
4. **Type Safety**: Fixed entry_price type handling for market orders (None -> 0.0)
5. **Code Quality**: Resolved all IDE diagnostics errors

### Test Results:
- 11 tests passing (up from 8)
- 3 critical bugs fixed (were xfail, now pass)
- 1 xfail remaining (mock-specific issue, not production bug)

## 1. CRITICAL: Unprotected Position Risk [✅ FIXED]
**File**: `src/project_x_py/order_manager/bracket_orders.py`
**Severity**: CRITICAL - Financial Risk
**Test**: `test_bracket_orders.py::test_bracket_order_emergency_close_on_failure`

### Issue
When protective orders (stop loss and take profit) fail to place after a bracket order entry is filled, the system returns success and leaves the position completely unprotected. This exposes traders to unlimited financial risk.

### Current Behavior
- Entry order fills successfully
- Stop loss order fails to place
- Take profit order fails to place
- Method returns `BracketOrderResponse(success=True, stop_order_id=None, target_order_id=None)`
- Position remains open with NO risk management

### Expected Behavior
- When protective orders fail, immediately close the position
- Raise `ProjectXOrderError` with clear message about unprotected position
- Log emergency closure attempt
- Return failure status to prevent false confidence

### Impact
Traders believe they have a protected position when they actually have unlimited risk exposure.

## 2. Recovery Manager Integration Broken
**File**: `src/project_x_py/order_manager/bracket_orders.py`
**Test**: `test_bracket_orders.py::test_bracket_order_with_recovery_manager`

### Issue
The `_get_recovery_manager()` method is called but doesn't properly access the recovery_manager attribute, preventing transaction rollback on failures.

### Current Behavior
- Code calls `self._get_recovery_manager()` at line 250
- Method exists at line 124 but doesn't access `self.recovery_manager`
- Recovery operations are never tracked

### Expected Behavior
- Recovery manager should track all bracket order operations
- Failed operations should trigger automatic rollback
- Partial failures should be recoverable

## 3. Missing Input Validation
**File**: `src/project_x_py/order_manager/bracket_orders.py`
**Tests**:
- `test_bracket_orders.py::test_bracket_order_invalid_entry_type`
- `test_bracket_orders.py::test_bracket_order_missing_entry_price_for_limit`

### Issues
1. No validation for `entry_type` parameter - accepts any string value
2. No validation for `None` entry_price - causes Decimal conversion error

### Current Behavior
- Any non-"market" entry_type is treated as "limit" (including invalid values)
- `None` entry_price causes `decimal.ConversionSyntax` error instead of validation error

### Expected Behavior
- Validate entry_type is only "market" or "limit"
- Validate entry_price is not None for limit orders
- Raise clear `ProjectXOrderError` with descriptive messages

## Recommendations

1. **IMMEDIATE**: Fix the unprotected position bug - this is a critical financial risk
2. **HIGH PRIORITY**: Fix recovery manager integration for proper transaction semantics
3. **MEDIUM**: Add input validation to prevent confusing errors

## Test Status
- 8 tests passing (correct behavior)
- 4 tests marked as xfail (documenting bugs)
- All tests properly reflect expected behavior, not current bugs
